<?xml version="1.0"?>
<robot name="irm2" 
       xmlns:xacro="http://www.ros.org/wiki/xacro">
<!-- Written by Ngo An Thuyen HCMUT - ViamLab 3-15-2021-->

<!-- AUV INERTIA ROTARY MASS  2 -->
  <link name="irm2_link">
    <visual>
      <geometry>
        <mesh filename="package://auv2000_description/dae/irm2.dae"/>
      </geometry>
    </visual>
    <!-- AUV INERTIA ROTARY MASS -->
    <collision name="IRM2">
      <origin xyz="0 0 0" rpy="0 1.570796327 0" />
      <geometry>
        <cylinder length="0.166" radius="0.079" />
      </geometry>
    </collision>

    <inertial>
      <origin xyz="0 0 -0.0626" rpy=" 0 0 0"/>
      <mass value="5.553972790"/>
      <inertia ixx="0.006657740236353" ixy="0.0" ixz="0.0" 
               iyy="2.454678883017721" iyz="0.0" 
               izz="2.455311107632614"/>
    </inertial>
  </link>

  <joint name="irm2_joint" type ="revolute">
    <origin xyz="-0.267 0 0" rpy="0 0 0" />
    <parent link="base_link"/>
    <child link="irm2_link"/>
    <safety_controller k_position="100" k_velocity="10000" soft_lower_limit="-0.53" soft_upper_limit="0.53"/>  
    <limit lower="-0.53" upper="0.53" effort="1" velocity="1"/> 
    <axis xyz = "1 0 0" />
  </joint>

 
    <transmission name="trans_irm_2">
    <type>transmission_interface/SimpleTransmission</type>
    <joint name="irm2_joint">
        <hardwareInterface>hardware_interface/EffortJointInterface</hardwareInterface>
    </joint>
    <actuator name="motor_irm2">
        <mechanicalReduction>1</mechanicalReduction>
    </actuator>
  </transmission>

</robot>
