<?xml version="1.0"?>
<robot name="mass_shifter" 
       xmlns:xacro="http://www.ros.org/wiki/xacro">
<!-- Written by Ngo An Thuyen HCMUT - ViamLab 3-15-2021-->

<!-- AUV MASS SHIFTER -->
  <link name="mass_shifter_link">
    <visual>
      <geometry>
        <mesh filename="package://auv2000_description/dae/mass_shifter.dae"/>
      </geometry>
    </visual>
    <!-- AUV MASS SHIFTER -->
    <collision name="MASS_SHIFTER">
      <origin xyz="0 0 0" rpy="0 1.570796327 0" />
      <geometry>
        <cylinder length="0.087" radius="0.098" />
      </geometry>
    </collision>

    <inertial>
      <origin xyz="0 0 0" rpy=" 0 0 0"/>
      <mass value="7.388178972"/>
       <inertia ixx="0.044331057716505" ixy="0.0" ixz="0.0" 
                iyy="2.599774330336140" iyz="0.0" 
                izz="2.612228548561526"/>
    </inertial>
  </link>

  <joint name="mass_shifter_joint" type ="prismatic"> 
    <axis xyz = "1 0 0" />
    <origin xyz="0.0213 0 0" rpy="0 0 0" />
    <parent link="base_link"/>
    <child link="mass_shifter_link"/>
    
    <safety_controller k_position="100" k_velocity="100" soft_lower_limit="-0.2" soft_upper_limit="0.2"/>
    <limit effort="2000" lower="-0.2" upper="0.2" velocity="200"/>
   
  </joint>

  <transmission name="trans_mass_shifter">
    <type>transmission_interface/SimpleTransmission</type>
    <joint name="mass_shifter_joint">
        <hardwareInterface>hardware_interface/EffortJointInterface</hardwareInterface>
    </joint>
    <actuator name="motor_mass_shifter">
        <mechanicalReduction>1</mechanicalReduction>
    </actuator>
  </transmission>

</robot>
