<?xml version="1.0"?>
<robot name="piston" 
       xmlns:xacro="http://www.ros.org/wiki/xacro">
<!-- Written by Ngo An Thuyen HCMUT - ViamLab 4-2-2021-->

<!-- AUV  PISTON CYCLINDER (Ballast) -->
  <link name="piston_link">
    <visual>
      <geometry>
         <cylinder length="0.02" radius="0.08" />
      </geometry>
    </visual>
    <!-- AAUV  PISTON CYCLINDER (Ballast) -->
    <collision name="piston">
      <origin xyz="0 0 0" rpy="0 1.570796327 0" />
      <geometry>
        <cylinder length="0.02" radius="0.08" />
      </geometry>
    </collision>

    <inertial>
      <origin xyz="0 0 0" rpy=" 0 0 0"/>
      <mass value="0.0001"/>
      <inertia ixx="0.0001" ixy="0.0" ixz="0.0" 
               iyy="0.0001" iyz="0.0" 
               izz="0.0001"/>
    </inertial>
  </link>

  <joint name="piston_joint" type ="prismatic">
    <origin xyz="0.405 0 0" rpy="0 1.57 0" />
    <parent link="base_link"/>
    <child link="piston_link"/>
     <axis xyz = "0 0 1" />
    <safety_controller k_position="100" k_velocity="10000" soft_lower_limit="0" soft_upper_limit="0.08"/> 

    <limit lower="0" upper="0.08" effort="0" velocity="0"/> 
    <axis xyz = "0 0 1" />
  </joint>

</robot>
