<?xml version="1.0"?>
<robot name="propeller" 
       xmlns:xacro="http://www.ros.org/wiki/xacro">
<!-- Written by Ngo An Thuyen HCMUT - ViamLab 3-15-2021-->

<!-- AUV PROPELLER -->
  <link name="propeller_link">
    <visual>
      <geometry>
        <mesh filename="package://auv2000_description/dae/propeller.dae"/>
      </geometry>
    </visual>
    <!-- AUV PROPELLER -->
    <collision name="PROPELLER">
      <origin xyz="0 0 0" rpy="0 1.57 0" />
      <geometry>
        <cylinder length="0.052" radius="0.0625" />
      </geometry>
    </collision>

    <inertial>
      <origin xyz="0 0 0" rpy=" 0 0 0"/>
      <mass value="0.14"/>
      <inertia ixx="0.03536589225573" ixy="0.0" ixz="0.0" 
               iyy="0.03619574038159" iyz="0.0" 
               izz="0.00212609181311"/>
    </inertial>
  </link>

  <joint name="propeller_joint" type ="continuous">
    <axis rpy="0 0 0" xyz="1 0 0"/>
    <origin xyz="-1.225 0 0" rpy="0 0 0" />
    <parent link="base_link"/>
    <child link="propeller_link"/>
  </joint>

</robot>
