<?xml version="1.0"?>
<robot name="rudder" 
       xmlns:xacro="http://www.ros.org/wiki/xacro">
<!-- Written by Ngo An Thuyen HCMUT - ViamLab 3-15-2021-->

<!-- AUV RUDDER -->
  <link name="rudder_link">
    <visual>
      <geometry>
        <mesh filename="package://auv2000_description/dae/rudder.dae"/>
      </geometry>
    </visual>
    <!-- AUV RUDDER -->
    <collision name="RUDDER">
      <origin xyz="0 0 0" rpy="0 0 3.14" />
      <geometry>
        <box size = "0.065 0.015 0.1" />
      </geometry>
    </collision>

    <inertial>
      <origin xyz="0 0 0" rpy=" 0 0 0"/>
      <mass value="0.086142809"/>
      <inertia ixx="0.00190754981851" ixy="0.0" ixz="0.0" 
               iyy="0.00049855719697" iyz="0.0" 
               izz="0.00237808757075"/>
    </inertial>
  </link>

  <joint name="rudder_joint" type ="revolute">
    <axis xyz="0 0 1"/>
    <limit effort="0" lower="-1.57" upper="1.57" velocity="0"/>
    <origin xyz="-1.295 0 0" rpy="0 0 3.14" />
    <parent link="base_link"/>
    <child link="rudder_link"/>
  </joint>

</robot>
